# try… catch vs then… catch

```jsx
const fetchTodo = () => {
      try {
        fetch(BASE_URL)
          .then((response) => {
            if (!response.ok) throw new Error("GET 요청 실패");
            return response.json();
          })
          .then((data) => {
            console.log("exe");
            setTodoList(data);
            setSuccess(true);
          });
      } catch (error) {
        console.log(typeof !!error);
        // setError(error);
        // setSuccess(false);
      }
      setLoading(false);
    };
    fetchTodo();
  }, []);
```

이 코드는 단단히 뒤틀린 코드다…

1. !response.ok는 에러를 발생시키지 않는다. 단순한 response의 상태일 뿐..
2. then…catch와 try…catch를 혼용해서 썻다.

## then…catch

- **`then-catch`** 는 비동기적인 프로세스에서 예외를 처리하는데 사용
- **`then`** 메서드를 사용하여 프로미스의 성공적인 결과를 처리하고, **`catch`** 메서드를 사용하여 프로미스가 rejected될 때 발생한 예외를 처리
- **`then`** 블록에서 발생한 예외는 자동으로 **`catch`** 블록으로 전달되지 않고, throw를 통해 error를 던져주거나 promise reject를 통해 error를 전달해야 함

```jsx
someAsyncFunction()
  .then((result) => {
    // 성공적인 결과 처리
    console.log(result);
    throw new Error("이 부분에서 에러 발생"); // 이거 또는
    return Promise.reject(new Error("이 부분에서 에러 발생")); // 이거
  })
  .catch((error) => {
    // 예외 처리
    console.error("에러 발생:", error);
  });
```

## try… catch

- **`try-catch`** 는 주로 동기적인 예외 처리
- **`try`** 블록 내에서 코드가 실행되다가 예외가 발생하면 **`catch`** 블록으로 제어가 이동하여 예외를 캐치하고 처리
- 예외가 발생하는 순간에 즉시 처리

```jsx
try {
  // 동기 코드
  // ...
} catch (error) {
  // 예외 처리
  console.error("에러 발생:", error);
}
```

## async await에서의 try…catch

- withTryCatch에서 catch 문에서 에러를 던졌는데, 이건 의미가 없고 try 문에서 던져줘야한다.
- async 함수를 실행한 후에 then…catch로 에러를 다루면 async 함수 안에서는 try…catch문을 사용할 필요가 없다.

```jsx
const makeError = async () => {
  throw new Error("에러 클래스에 의한 에러");
};

const withTryCatch = async () => {
  try {
    console.log("try-cath 를 사용한 async");
    const result = await makeError();
    console.log("withTryCatch - 에러가 발생하는 위치 아래에 있는 코드 (실행되면 안됨)");
    return result;
  } catch (err) {
    throw err;
  }
};

const withoutTryCatch = async () => {
  console.log("try-cath 없는 async");
  const result = await makeError();
  console.log("withoutTryCatch - 에러가 발생하는 위치 아래에 있는 코드 (실행되면 안됨)");
  return result;
};

withTryCatch()
  .then((res) => {
    console.log("withTryCatch - 성공결과", res);
  })
  .catch((err) => {
    console.log("withTryCatch - 실패결과", err.message);
  });

withoutTryCatch()
  .then((res) => {
    console.log("withoutTryCatch - 성공결과", res);
  })
  .catch((err) => {
    console.log("withoutTryCatch - 실패결과", err.message);
  });
```
